Workbook

Sheet Config
A1: Key | B1: Value | C1: Description | D1: Status | E1: LastUpdated
A2: growth_A | B2: 5 | C2: 성장 공식 1회차 기준값 (필요_성장포인트 = A × r^(n-1)) | D2: Planning | E2: 46209
A3: growth_r | B3: 1.35 | C3: 성장률 (1보다 큼, 클수록 후반 성장이 급격히 둔화) | D3: Planning | E3: 46209
A4: growth_tag_mult_base | B4: 0.25 | C4: 성장 태그 배율 기본값 (태그 0개일 때) | D4: Planning | E4: 46209
A5: growth_tag_mult_step | B5: 0.25 | C5: 성장 태그 1개당 배율 증가폭 (배율 = base + step × 태그수) | D5: Planning | E5: 46209
A6: stamina_penalty_rate | B6: 0.5 | C6: 스태미너 0일 때 1차 스탯 실효치 감소율 (0.5 = 50% 감소) | D6: Planning | E6: 46209
A7: flee_chance_base | B7: 0.9 | C7: 기본 도망(귀환) 성공 확률 (0.9 = 90%, 아이템 옵션으로 변동 가능) | D7: Planning | E7: 46209
A8: medicine_slot_default | B8: 5 | C8: 약품 기본 소지 가능 개수 | D8: Planning | E8: 46209
A9: status_proc_min | B9: 0.05 | C9: 상태이상 발생 확률 하한 (5%) | D9: Planning | E9: 46211
A10: status_proc_max | B10: 0.25 | C10: 상태이상 발생 확률 상한 (25%) | D10: Planning | E10: 46211
A11: shop_stock_reset_interval | B11: 3 | C11: 상점 재고 리셋 주기 (출정 N회마다 재고 복구, 3 = 3회 출정마다) | D11: Planning | E11: 46211
A12: defense_constant | B12: 60 | C12: 방어력 공식 상수 K (최종뎀 = 데미지 × K/(K+방어력), 작을수록 방어력 영향 큼) | D12: Planning | E12: 46211
A13: crit_proc_min | B13: 0.05 | C13: 크리티컬 발생 확률 하한 (5%) | D13: Planning | E13: 46211
... A15: crit_damage_mult | B15: 1.5 | C15: 크리티컬 데미지 배수 (방어 적용 전 데미지에 곱함) | D15: Planning | E15: 46211
A16: start_vault_items | B16: weapon_wooden_sword,armor_cloth_hood | C16: 시작시 금고에 지금되는 아이템 ID 목록(쉼표 구분) | D16: Planning | E16: 46213
A17: start_sato | B17: 1000 | C17: 시작 사토 잔액 | D17: Planning | E17: 46213
A18: start_primary_stats | B18: 10,10,10,10 | C18: 1차 스탯 초기치(힘,민첩,체력,의지) | D18: Planning | E18: 46213

Sheet PrimaryStat
A1: PrimaryStatID | B1: StatName_KR | C1: StatName_EN | D1: Role_KR | E1: GrowthCondition | F1: GrowthPointPerTrigger | G1: Status | H1: Notes | I1: LastUpdated
A2: stat_str | B2: 힘 | C2: Strength | D2: 물리적 힘과 공격력 중심 | E2: 공격이 적에게 명중(적중)한 횟수 | F2: 1 | G2: Planning | H2: 1차 스탯 | I2: 46209
A3: stat_dex | B3: 민첩 | C3: Dexterity | D3: 속도·정확도·회피 중심 | E3: 회피에 성공한 횟수 | F3: 2 | G3: Planning | H3: 1차 스탯 | I3: 46209
A4: stat_vit | B4: 체력 | C4: Vitality | D4: 생존과 내구력 중심 | E4: 피격당한 횟수(피해량과 무관) | F4: 1.5 | G4: Planning | H4: 1차 스탯 | I4: 46209
A5: stat_will | B5: 의지 | C5: Will | D5: 정신력·저항·변수 중심 | E5: 크리티컬 공격에 성공한 횟수 | F5: 4 | G5: Planning | H5: 1차 스탯 | I5: 46209

Sheet SecondaryStat
A1: SecondaryStatID | B1: SecondaryStat_KR | C1: SecondaryStat_EN | D1: SourcePrimary | E1: ValuePerPoint | F1: BaseValue | G1: Cap | H1: Unit | I1: Influence | J1: Description | K1: Status | L1: Notes | M1: LastUpdated
A2: sec_min_atk | B2: 최소 공격력 | C2: Min Attack | D2: stat_str | E2: 0.08 | F2: 0 | G2: - | H2: 고정 | I2: 강함 | J2: 기본 공격력의 하한선 | K2: Planning | L2: - | M2: 46211
A3: sec_max_atk | B3: 최대 공격력 | C3: Max Attack | D3: stat_str | E3: 0.12 | F3: 0 | G3: - | H3: 고정 | I3: 강함 | J3: 기본 공격력의 상한선 | K3: Planning | L3: - | M3: 46211
A4: sec_defense | B4: 방어력 | C4: Defense | D4: stat_str | E4: 0.06 | F4: 0 | G4: - | H4: 고정 | I4: 중간 | J4: 물리 피해 감소 (힘 기여분) | K4: Planning | L4: 방어력은 힘+체력 합산 | M4: 46211
A5: sec_atk_speed | B5: 공격 속도 | C5: Attack Speed | D5: stat_dex | E5: 0.015 | F5: 1 | G5: 3 | H5: 퍼센트 | I5: 강함 | J5: 초당 공격 횟수 (base=맨손, 무기가 대체) | K5: Planning | L5: cap=템포 상한 | M5: 46211
A6: sec_evasion | B6: 회피율 | C6: Evasion | D6: stat_dex | E6: 0.08 | F6: 0 | G6: - | H6: 퍼센트 | I6: 강함 | J6: 물리 공격 회피 확률 (명중 비율식) | K6: Planning | L6: - | M6: 46211
A7: sec_accuracy | B7: 적중률 | C7: Accuracy | D7: stat_dex | E7: 0.06 | F7: 0 | G7: - | H7: 퍼센트 | I7: 강함 | J7: 공격이 빗나가지 않을 확률 (명중 비율식) | K7: Planning | L7: - | M7: 46211
A8: sec_max_hp | B8: 최대 생명력 | C8: Max HP | D8: stat_vit | E8: 1.2 | F8: 100 | G8: - | H8: 고정 | I8: 강함 | J8: 최대 체력 | K8: Planning | L8: base=기본 생명력 | M8: 46211
A9: sec_defense | B9: 방어력 | C9: Defense | D9: stat_vit | E9: 0.05 | F9: 0 | G9: - | H9: 고정 | I9: 중간 | J9: 물리 피해 감소 (체력 기여분) | K9: Planning | L9: 방어력은 힘+체력 합산 | M9: 46211
A10: sec_status_resist | B10: 상태이상 저항 | C10: Status Resist | D10: stat_vit | E10: 0.2 | F10: 0 | G10: - | H10: 퍼센트 | I10: 중간 | J10: 기절·출혈·파열 등 저항 | K10: Planning | L10: 저항은 체력+의지 합산 | M10: 46211
A11: sec_crit_chance | B11: 크리티컬 확률 | C11: Crit Chance | D11: stat_will | E11: 0.07 | F11: 2 | G11: - | H11: 퍼센트 | I11: 중간 | J11: 치명타 발생 확률 (base=기본 크리확률) | K11: Planning | L11: 밴드 매핑으로 cap 불필요 | M11: 46211
A12: sec_crit_resist | B12: 크리티컬 저항 | C12: Crit Resist | D12: stat_will | E12: 0.05 | F12: 5 | G12: - | H12: 퍼센트 | I12: 중간 | J12: 치명타 발생 저항 (크리확률과 비율식) | K12: Planning | L12: 신설·값 잠정 | M12: 46211
A13: sec_status_resist | B13: 상태이상 저항 | C13: Status Resist | D13: stat_will | E13: 0.25 | F13: 0 | G13: - | H13: 퍼센트 | I13: 강함 | J13: 기절·출혈·파열 등 저항 | K13: Planning | L13: 저항은 체력+의지 합산 | M13: 46211

Sheet WeaponAttribute
A1: AttributeName_EN | B1: StatusEffect_KR | C1: EffectSummary | D1: Status | E1: Notes | F1: LastUpdated
A2: Stun | B2: 기절 | C2: 대상을 일정 시간 행동 불가 상태로 만든다 (제어) | D2: Planning | F2: 46206
A3: Bleed | B3: 출혈 | C3: 일정 시간 동안 지속 피해를 준다 (도트) | D3: Planning | F3: 46206
A4: Pierce | B4: 관통 | C4: 이번 타격에 대상 방어력의 일정 %를 무시한다 | D4: Planning | F4: 46206
A5: Rupture | B5: 파열 | C5: 일정 시간 대상의 방어력을 감소시킨다 | D5: Planning | F5: 46206
A6: Sever | B6: 절단 | C6: 일정 시간 대상의 공격력을 감소시킨다 | D6: Planning | F6: 46206

Sheet StatusEffect
A1: StatusID | B1: Name_KR | C1: Name_EN | D1: Attribute | E1: EffectType | F1: ScaleSource | G1: Reapply | H1: IgnoreDefense | I1: Value | J1: ValueMax | K1: PerStack | L1: TickInterval | M1: Duration | N1: MaxStack | O1: Formula | P1: Status | Q1: Notes | R1: LastUpdated
A2: status_bleed | B2: 출혈 | C2: Bleed | D2: bleed | E2: dot_damage | F2: weapon_max_dmg | G2: time_reset | H2: Y | I2: 0.5 | J2: - | K2: - | L2: 2 | M2: 4 | N2: 3 | O2: 스택당 무기 최대데미지×50% 피해, 2초당 1회 발동, 방어무시, 재부여 시 시간리셋+스택유지 | P2: Planning | Q2: 베기 계열 | R2: 46210
A3: status_stun | B3: 기절 | C3: Stun | D3: stun | E3: attack_delay | F3: weapon_atkspd_inverse | G3: - | H3: N | I3: 0.5 | J3: - | K3: - | L3: - | M3: - | N3: 1 | O3: 다음 공격 지연 = (1÷무기 공격속도)×50%, 스택 없음(단일) | P3: Planning | Q3: 둔기 계열 | R3: 46210
A4: status_pierce | B4: 관통 | C4: Pierce | D4: pierce | E4: defense_ignore | F4: target_defense | G4: - | H4: N | I4: 0.05 | J4: 0.4 | K4: - | L4: - | M4: - | N4: - | O4: 발생 시 상대 방어력의 5~40% 랜덤 무시(해당 일격만), 즉발 | P4: Planning | Q4: 찌르기 계열 | R4: 46210
A5: status_rupture | B5: 파열 | C5: Rupture | D5: rupture | E5: attack_reduction | F5: target_attack | G5: time_reset | H5: N | I5: 0.1 | J5: - | K5: 0.05 | L5: - | M5: 3 | N5: 3 | O5: 상대 공격력 감소(지속 중 상시), 스택당 10/15/20%(기본0.10+스택당0.05), 지속 3초 | P5: Planning | Q5: 타격 계열 | R5: 46210
A8: ■ 참고 (컬럼 값 설명)
A9: EffectType | B9: dot_damage | C9: 지속피해
B10: attack_delay | C10: 공격지연
B11: defense_ignore | C11: 방어무시
B12: attack_reduction | C12: 공격력감소
A13: ScaleSource | B13: weapon_max_dmg | C13: 무기 최대뎀에 비례
B14: weapon_atkspd_inverse | C14: 1÷무기 공격속도에 비례
B15: target_defense | C15: 상대 방어력에 비례
B16: target_attack | C16: 상대 공격력에 비례
A17: 튜닝 손잡이 | B17: Value | C17: 기본 계수 (예: 출혈 세기 = 0.5)
B18: ValueMax | C18: 랜덤 상한 (예: 관통 상한 = 0.40)
B19: PerStack | C19: 스택당 증가폭 (예: 파열 = 0.05)
A20: 기호 | B20: - | C20: 이 효과엔 해당 없음
B21: TBD | C21: 부여력(발생 확률), 저항과 함께 추후 확정

Sheet Affix
A1: AffixID | B1: AffixName_KR | C1: AffixType | D1: Category | E1: GroupID | F1: TargetStat | G1: TargetStat_KR | H1: Value_Min | I1: Value_Max | J1: Weight | K1: Status | L1: Notes | M1: LastUpdated
A2: affix_p01 | B2: 억센 | C2: prefix | D2: weapon | E2: wea1 | F2: stat_str | G2: 힘 | H2: 1 | I2: 3 | J2: 40 | K2: Planning | L2: 1차 증가 | M2: 46209
A3: affix_p02 | B3: 육중한 | C3: prefix | D3: weapon | E3: wea1 | F3: sec_max_atk | G3: 최대 공격력 | H3: 2 | I3: 5 | J3: 35 | K3: Planning | L3: 2차 증가 | M3: 46209
A4: affix_p03 | B4: 둔한 | C4: prefix | D4: weapon | E4: wea1 | F4: sec_evasion | G4: 회피율 | H4: -4 | I4: -1 | J4: 25 | K4: Planning | L4: 2차 감소(트레이드오프) | M4: 46209
A5: affix_p04 | B5: 날카로운 | C5: prefix | D5: weapon | E5: wea2 | F5: sec_min_atk | G5: 최소 공격력 | H5: 1 | I5: 3 | J5: 45 | K5: Planning | L5: 2차 증가 | M5: 46209
A6: affix_p05 | B6: 잔혹한 | C6: prefix | D6: weapon | E6: wea2 | F6: sec_crit_chance | G6: 크리티컬 확률 | H6: 1 | I6: 4 | J6: 30 | K6: Planning | L6: 2차 증가 | M6: 46209
A7: affix_s01 | B7: 곰의 | C7: suffix | D7: weapon | E7: wea1 | F7: stat_vit | G7: 체력 | H7: 1 | I7: 3 | J7: 40 | K7: Planning | L7: 1차 증가 | M7: 46209
A8: affix_s02 | B8: 방벽의 | C8: suffix | D8: weapon | E8: wea1 | F8: sec_defense | G8: 방어력 | H8: 1 | I8: 3 | J8: 35 | K8: Planning | L8: 2차 증가 | M8: 46209
A9: affix_s03 | B9: 무딘 | C9: suffix | D9: weapon | E9: wea1 | F9: sec_accuracy | G9: 적중률 | H9: -3 | I9: -1 | J9: 25 | K9: Planning | L9: 2차 감소 | M9: 46209
A10: affix_s04 | B10: 표범의 | C10: suffix | D10: weapon | E10: wea2 | F10: stat_dex | G10: 민첩 | H10: 1 | I10: 3 | J10: 40 | K10: Planning | L10: 1차 증가 | M10: 46209
A11: affix_s05 | B11: 광기의 | C11: suffix | D11: weapon | E11: wea2 | F11: sec_crit_chance | G11: 크리티컬 확률 | H11: 2 | I11: 5 | J11: 30 | K11: Planning | L11: 2차 증가 | M11: 46209
A12: affix_p06 | B12: 단단한 | C12: prefix | D12: armor | E12: arm1 | F12: sec_defense | G12: 방어력 | H12: 1 | I12: 3 | J12: 40 | K12: Planning | L12: 예시 그룹 배치 | M12: 46209
A13: affix_p07 | B13: 매서운 | C13: prefix | D13: armor | E13: arm3 | F13: sec_accuracy | G13: 적중률 | H13: 1 | I13: 3 | J13: 35 | K13: Planning | L13: 예시 그룹 배치 | M13: 46209
... A22: affix_s10 | B22: 재생의 | C22: suffix | D22: armor | E22: arm1 | F22: sec_max_hp | G22: 최대 생명력 | H22: 3 | I22: 8 | J22: 25 | K22: Planning | L22: 예시 그룹 배치 | M22: 46209
C23: suffix | D23: armor | E23: arm2 | L23: 예시 그룹 배치
C24: suffix | D24: armor | E24: arm3 | L24: 예시 그룹 배치
C25: suffix | D25: armor | E25: arm4 | L25: 예시 그룹 배치
C26: suffix | D26: armor | E26: arm3 | L26: 예시 그룹 배치
C27: suffix | D27: armor | E27: arm1 | L27: 예시 그룹 배치
C28: suffix | D28: armor | E28: arm3 | L28: 예시 그룹 배치
C29: suffix | D29: armor | E29: arm1 | L29: 예시 그룹 배치

Sheet Artifact
A1: ArtifactID | B1: ArtifactName_KR | C1: ArtifactName_EN | D1: Category | E1: Slot | F1: Stat1 | G1: Stat1_KR | H1: Value1_Low | I1: Value1_High | J1: Stat2 | K1: Stat2_KR | L1: Value2_Low | M1: Value2_High | N1: GrowthTag_Str | O1: GrowthTag_Dex | P1: GrowthTag_Vit | Q1: GrowthTag_Will | R1: MaxDurability | S1: DropRate | T1: Status | U1: Notes | V1: LastUpdated
A2: art_watch_worn | B2: 낡은 손목시계 | C2: Worn Wristwatch | D2: Artifact_Worn | E2: 1 | F2: stat_dex | G2: 민첩 | H2: 1 | I2: 2 | J2: - | K2: - | L2: - | M2: - | N2: 0 | O2: 1 | P2: 0 | Q2: 0 | R2: 45 | S2: 9 | T2: Planning | U2: 착장형·소량 상승 | V2: 46211
A3: art_ring_iron | B3: 무쇠 반지 | C3: Iron Ring | D3: Artifact_Worn | E3: 1 | F3: stat_str | G3: 힘 | H3: 1 | I3: 2 | J3: - | K3: - | L3: - | M3: - | N3: 1 | O3: 0 | P3: 0 | Q3: 0 | R3: 45 | S3: 9 | T3: Planning | U3: 착장형·소량 상승 | V3: 46211
A4: art_necklace_old | B4: 오래된 목걸이 | C4: Old Necklace | D4: Artifact_Worn | E4: 1 | F4: stat_will | G4: 의지 | H4: 1 | I4: 2 | J4: - | K4: - | L4: - | M4: - | N4: 0 | O4: 0 | P4: 0 | Q4: 1 | R4: 45 | S4: 9 | T4: Planning | U4: 착장형·소량 상승 | V4: 46211
A5: art_shoes_worn | B5: 낡은 운동화 | C5: Worn Sneakers | D5: Artifact_Worn | E5: 1 | F5: stat_dex | G5: 민첩 | H5: 1 | I5: 2 | J5: - | K5: - | L5: - | M5: - | N5: 0 | O5: 1 | P5: 0 | Q5: 0 | R5: 45 | S5: 9 | T5: Planning | U5: 착장형·소량 상승 | V5: 46211
A6: art_boots_heavy | B6: 무거운 군화 | C6: Heavy Combat Boots | D6: Artifact_Worn | E6: 1 | F6: stat_vit | G6: 체력 | H6: 4 | I6: 6 | J6: stat_dex | K6: 민첩 | L6: -5 | M6: -3 | N6: 0 | O6: 0 | P6: 1 | Q6: 0 | R6: 50 | S6: 5 | T6: Planning | U6: 착장형·회피↓+체력태그 조합 예시 | V6: 46211
A7: art_charm_paper | B7: 종이 부적 | C7: Paper Charm | D7: Artifact_Carried | E7: 2 | F7: sec_accuracy | G7: 적중률 | H7: 1 | I7: 3 | J7: - | K7: - | L7: - | M7: - | N7: 0 | O7: 1 | P7: 0 | Q7: 0 | R7: 40 | S7: 10 | T7: Planning | U7: 소지형·소량 상승 | V7: 46211
A8: art_magazine_old | B8: 옛날 잡지 | C8: Old Magazine | D8: Artifact_Carried | E8: 2 | F8: sec_crit_chance | G8: 크리티컬 확률 | H8: 1 | I8: 3 | J8: - | K8: - | L8: - | M8: - | N8: 0 | O8: 0 | P8: 0 | Q8: 1 | R8: 40 | S8: 10 | T8: Planning | U8: 소지형·소량 상승 | V8: 46211
A9: art_keychain_metal | B9: 금속 열쇠고리 | C9: Metal Keychain | D9: Artifact_Carried | E9: 2 | F9: sec_evasion | G9: 회피율 | H9: 1 | I9: 3 | J9: - | K9: - | L9: - | M9: - | N9: 0 | O9: 1 | P9: 0 | Q9: 0 | R9: 40 | S9: 10 | T9: Planning | U9: 소지형·소량 상승 | V9: 46211
A10: art_doll_worn | B10: 낡은 인형 | C10: Worn Doll | D10: Artifact_Carried | E10: 2 | F10: sec_status_resist | G10: 상태이상 저항 | H10: 1 | I10: 3 | J10: - | K10: - | L10: - | M10: - | N10: 0 | O10: 0 | P10: 1 | Q10: 0 | R10: 40 | S10: 10 | T10: Planning | U10: 소지형·소량 상승 | V10: 46211
A11: art_book_heavy | B11: 두꺼운 책 | C11: Heavy Book | D11: Artifact_Carried | E11: 2 | F11: sec_defense | G11: 방어력 | H11: 5 | I11: 8 | J11: sec_atk_speed | K11: 공격 속도 | L11: -7 | M11: -4 | N11: 1 | O11: 0 | P11: 0 | Q11: 0 | R11: 48 | S11: 5 | T11: Planning | U11: 소지형·방어↑+공속↓ 트레이드오프 | V11: 46211

Sheet Shop
A1: ShopID | B1: ItemName_KR | C1: ItemName_EN | D1: ItemID | E1: Category | F1: BuyPrice | G1: StockMax | H1: Status | I1: Notes | J1: LastUpdated
A2: shop_clinic | B2: 붕대 | C2: {=IF($B2="","",IFERROR(XLOOKUP($B2,All_IDs!$B:$B,All_IDs!$C:$C),""))} -> Bandage | D2: {=IF($B2="","",IFERROR(XLOOKUP($B2,All_IDs!$B:$B,All_IDs!$A:$A),""))} -> item_med_bandage | E2: {=IF($B2="","",IFERROR(XLOOKUP($B2,All_IDs!$B:$B,All_IDs!$D:$D),""))} -> Medicine | F2: 150 | G2: 10
A3: shop_clinic | B3: 응급 키트 | C3: {=IF($B3="","",IFERROR(XLOOKUP($B3,All_IDs!$B:$B,All_IDs!$C:$C),""))} -> First-aid Kit | D3: {=IF($B3="","",IFERROR(XLOOKUP($B3,All_IDs!$B:$B,All_IDs!$A:$A),""))} -> item_med_kit | E3: {=IF($B3="","",IFERROR(XLOOKUP($B3,All_IDs!$B:$B,All_IDs!$D:$D),""))} -> Medicine | F3: 500 | G3: 10
A4: shop_clinic | B4: 지혈 주사기 | C4: {=IF($B4="","",IFERROR(XLOOKUP($B4,All_IDs!$B:$B,All_IDs!$C:$C),""))} -> Hemostatic Syringe | D4: {=IF($B4="","",IFERROR(XLOOKUP($B4,All_IDs!$B:$B,All_IDs!$A:$A),""))} -> item_med_syringe | E4: {=IF($B4="","",IFERROR(XLOOKUP($B4,All_IDs!$B:$B,All_IDs!$D:$D),""))} -> Medicine | F4: 1500 | G4: 5
C5: {=IF($B5="","",IFERROR(XLOOKUP($B5,All_IDs!$B:$B,All_IDs!$C:$C),""))} | D5: {=IF($B5="","",IFERROR(XLOOKUP($B5,All_IDs!$B:$B,All_IDs!$A:$A),""))} | E5: {=IF($B5="","",IFERROR(XLOOKUP($B5,All_IDs!$B:$B,All_IDs!$D:$D),""))}
C6: {=IF($B6="","",IFERROR(XLOOKUP($B6,All_IDs!$B:$B,All_IDs!$C:$C),""))} | D6: {=IF($B6="","",IFERROR(XLOOKUP($B6,All_IDs!$B:$B,All_IDs!$A:$A),""))} | E6: {=IF($B6="","",IFERROR(XLOOKUP($B6,All_IDs!$B:$B,All_IDs!$D:$D),""))}
C7: {=IF($B7="","",IFERROR(XLOOKUP($B7,All_IDs!$B:$B,All_IDs!$C:$C),""))} | D7: {=IF($B7="","",IFERROR(XLOOKUP($B7,All_IDs!$B:$B,All_IDs!$A:$A),""))} | E7: {=IF($B7="","",IFERROR(XLOOKUP($B7,All_IDs!$B:$B,All_IDs!$D:$D),""))}
C8: {=IF($B8="","",IFERROR(XLOOKUP($B8,All_IDs!$B:$B,All_IDs!$C:$C),""))} | D8: {=IF($B8="","",IFERROR(XLOOKUP($B8,All_IDs!$B:$B,All_IDs!$A:$A),""))} | E8: {=IF($B8="","",IFERROR(XLOOKUP($B8,All_IDs!$B:$B,All_IDs!$D:$D),""))}
C9: {=IF($B9="","",IFERROR(XLOOKUP($B9,All_IDs!$B:$B,All_IDs!$C:$C),""))} | D9: {=IF($B9="","",IFERROR(XLOOKUP($B9,All_IDs!$B:$B,All_IDs!$A:$A),""))} | E9: {=IF($B9="","",IFERROR(XLOOKUP($B9,All_IDs!$B:$B,All_IDs!$D:$D),""))}
C10: {=IF($B10="","",IFERROR(XLOOKUP($B10,All_IDs!$B:$B,All_IDs!$C:$C),""))} | D10: {=IF($B10="","",IFERROR(XLOOKUP($B10,All_IDs!$B:$B,All_IDs!$A:$A),""))} | E10: {=IF($B10="","",IFERROR(XLOOKUP($B10,All_IDs!$B:$B,All_IDs!$D:$D),""))}
C11: {=IF($B11="","",IFERROR(XLOOKUP($B11,All_IDs!$B:$B,All_IDs!$C:$C),""))} | D11: {=IF($B11="","",IFERROR(XLOOKUP($B11,All_IDs!$B:$B,All_IDs!$A:$A),""))} | E11: {=IF($B11="","",IFERROR(XLOOKUP($B11,All_IDs!$B:$B,All_IDs!$D:$D),""))}
C12: {=IF($B12="","",IFERROR(XLOOKUP($B12,All_IDs!$B:$B,All_IDs!$C:$C),""))} | D12: {=IF($B12="","",IFERROR(XLOOKUP($B12,All_IDs!$B:$B,All_IDs!$A:$A),""))} | E12: {=IF($B12="","",IFERROR(XLOOKUP($B12,All_IDs!$B:$B,All_IDs!$D:$D),""))}
C13: {=IF($B13="","",IFERROR(XLOOKUP($B13,All_IDs!$B:$B,All_IDs!$C:$C),""))} | D13: {=IF($B13="","",IFERROR(XLOOKUP($B13,All_IDs!$B:$B,All_IDs!$A:$A),""))} | E13: {=IF($B13="","",IFERROR(XLOOKUP($B13,All_IDs!$B:$B,All_IDs!$D:$D),""))}
C14: {=IF($B14="","",IFERROR(XLOOKUP($B14,All_IDs!$B:$B,All_IDs!$C:$C),""))} | D14: {=IF($B14="","",IFERROR(XLOOKUP($B14,All_IDs!$B:$B,All_IDs!$A:$A),""))} | E14: {=IF($B14="","",IFERROR(XLOOKUP($B14,All_IDs!$B:$B,All_IDs!$D:$D),""))}
C15: {=IF($B15="","",IFERROR(XLOOKUP($B15,All_IDs!$B:$B,All_IDs!$C:$C),""))} | D15: {=IF($B15="","",IFERROR(XLOOKUP($B15,All_IDs!$B:$B,All_IDs!$A:$A),""))} | E15: {=IF($B15="","",IFERROR(XLOOKUP($B15,All_IDs!$B:$B,All_IDs!$D:$D),""))}
C16: {=IF($B16="","",IFERROR(XLOOKUP($B16,All_IDs!$B:$B,All_IDs!$C:$C),""))} | D16: {=IF($B16="","",IFERROR(XLOOKUP($B16,All_IDs!$B:$B,All_IDs!$A:$A),""))} | E16: {=IF($B16="","",IFERROR(XLOOKUP($B16,All_IDs!$B:$B,All_IDs!$D:$D),""))}
... C59: {=IF($B59="","",IFERROR(XLOOKUP($B59,All_IDs!$B:$B,All_IDs!$C:$C),""))} | D59: {=IF($B59="","",IFERROR(XLOOKUP($B59,All_IDs!$B:$B,All_IDs!$A:$A),""))} | E59: {=IF($B59="","",IFERROR(XLOOKUP($B59,All_IDs!$B:$B,All_IDs!$D:$D),""))}

Sheet Item
A1: ItemID | B1: ItemName_KR | C1: ItemName_EN | D1: Category | E1: Description | F1: MaxStack | G1: SellPrice | H1: EffectType | I1: EffectStat | J1: EffectValue | K1: EffectDuration | L1: Status | M1: Notes | N1: LastUpdated
A2: item_scrap_metal | B2: 고철 | C2: Scrap Metal | D2: Junk | E2: 여기저기 굴러다니는 고철. 수리·강화 재료로 쓰인다. | F2: 99 | G2: 15 | H2: none | L2: Planning | M2: 강화/수리 재료 | N2: 46209
A3: item_electronic_parts | B3: 전자 부품 | C3: Electronic Parts | D3: Junk | E3: 고장난 기기에서 뜯어낸 전자 부품. | F3: 99 | G3: 30 | H3: none | L3: Planning | M3: 재료 | N3: 46209
A4: item_machine_parts | B4: 기계 부품 | C4: Machine Parts | D4: Junk | E4: 기계에서 나온 정교한 부품. | F4: 99 | G4: 35 | H4: none | L4: Planning | M4: 재료 | N4: 46209
A5: item_mutant_tissue | B5: 변이 조직 | C5: Mutant Tissue | D5: Junk | E5: 변이체에게서 채취한 기이한 조직. | F5: 99 | G5: 40 | H5: none | L5: Planning | M5: 희귀 재료 | N5: 46209
A6: item_old_rope | B6: 낡은 로프 | C6: Old Rope | D6: Junk | E6: 해지고 낡은 밧줄. 팔면 약간의 돈이 된다. | F6: 99 | G6: 10 | H6: none | L6: Planning | M6: 판매용 | N6: 46209
A7: item_food_coffee | B7: 원두 한 줌 | C7: Handful of Coffee Beans | D7: Food | E7: 진짜 원두. 안전가옥에서 내려 마시면 잠시 정신이 맑아진다. | F7: 5 | G7: 120 | H7: buff | I7: atk_speed | J7: 8 | K7: 2 | L7: Planning | M7: 버프 전용(안전가옥) | N7: 46209
A8: item_food_jerky | B8: 훈제육 | C8: Smoked Jerky | D8: Food | E8: 제대로 조리한 고기. 포만감이 스태미너를 채워준다. | F8: 10 | G8: 90 | H8: stamina | J8: 30 | L8: Planning | M8: 스태미너 회복 | N8: 46209
A9: item_food_stew | B9: 영양 스튜 | C9: Nourishing Stew | D9: Food | E9: 김이 오르는 따뜻한 스튜. 스태미너를 채워준다. | F9: 5 | G9: 180 | H9: stamina | J9: 25 | L9: Planning | M9: 스태미너 회복 | N9: 46209
A10: item_food_canfruit | B10: 통조림 과일 | C10: Canned Fruit | D10: Food | E10: 달콤한 시럽에 절인 과일. 소소한 스태미너를 회복한다. | F10: 10 | G10: 50 | H10: stamina | J10: 15 | L10: Planning | M10: 하급 스태미너 회복 | N10: 46209
A11: item_food_energybar | B11: 비상 식량바 | C11: Emergency Ration Bar | D11: Food | E11: 딱딱하지만 든든한 비상용 식량. 스태미너를 크게 회복한다. | F11: 10 | G11: 140 | H11: stamina | J11: 45 | L11: Planning | M11: 상급 스태미너 회복 | N11: 46209
A12: item_med_bandage | B12: 붕대 | C12: Bandage | D12: Medicine | E12: 출정 중 상처를 감아 체력을 회복한다. | F12: 5 | G12: 45 | H12: heal | J12: 25 | L12: Planning | M12: 하급 회복 | N12: 46209
A13: item_med_kit | B13: 응급 키트 | C13: First-aid Kit | D13: Medicine | E13: 기본적인 응급 처치 도구. 체력을 회복한다. | F13: 5 | G13: 80 | H13: heal | J13: 40 | L13: Planning | M13: 중급 회복 | N13: 46209
A14: item_med_syringe | B14: 지혈 주사기 | C14: Hemostatic Syringe | D14: Medicine | E14: 즉시 많은 체력을 회복하는 고급 회복제. | F14: 5 | G14: 280 | H14: heal | J14: 65 | L14: Planning | M14: 고급 회복 | N14: 46209
A15: item_med_painkiller | B15: 진통제 | C15: Painkiller | D15: Medicine | E15: 통증을 억누르고 소량의 체력을 회복한다. | F15: 5 | G15: 35 | H15: heal | J15: 18 | L15: Planning | M15: 하급 회복 | N15: 46209
A16: item_med_antidote | B16: 해독제 | C16: Antidote | D16: Medicine | E16: 오염된 상처를 치료하며 체력을 회복한다. | F16: 5 | G16: 110 | H16: heal | J16: 50 | L16: Planning | M16: 중상급 회복 | N16: 46209
A17: item_quest_photo | B17: 낡은 사진 | C17: Old Photograph | D17: Quest | E17: 누군가에게 전달해야 하는 빛바랜 사진. | F17: 1 | G17: 0 | H17: none | L17: Planning | M17: 퀘스트 예시 | N17: 46209
A18: item_quest_dogtag | B18: 낡은 군번줄 | C18: Worn Dog Tag | D18: Quest | E18: 이름이 새겨진 낡은 군번줄. 사연이 있어 보인다. | F18: 1 | G18: 0 | H18: none | L18: Planning | M18: 퀘스트 예시 | N18: 46209
A19: item_quest_letter | B19: 봉인된 편지 | C19: Sealed Letter | D19: Quest | E19: 누군가에 남겨진 편지, 어디에서 누구에게 기록된건지 알 수가없다. | F19: 1 | G19: 0 | H19: none | L19: Planning | M19: 퀘스트 예시 | N19: 46209
A20: item_quest_keydata | B20: 손상된 USB | C20: Damaged USB | D20: Quest | E20: 일부 데이터가 남아있는 손상된 USB. 누군가 찾고 있다. | F20: 1 | G20: 0 | H20: none | L20: Planning | M20: 퀘스트 예시 | N20: 46209
A21: item_quest_medallion | B21: 빛바랜 훈장 | C21: Faded Medallion | D21: Quest | E21: 오래된 군용 훈장. 주인에게 의미가 있어 보인다. | F21: 1 | G21: 0 | H21: none | L21: Planning | M21: 퀘스트 예시 | N21: 46209
A22: item_police_keycard | B22: 경찰서 키카드 | C22: Police Keycard | D22: Key | E22: 봉쇄된 경찰서의 비상 셔터를 여는 키카드. | F22: 1 | G22: 0 | H22: none | L22: Planning | M22: 히든존 언락(city_01_police) | N22: 46209
A23: item_submarine_key | B23: 잠수함 해치 키 | C23: Submarine Hatch Key | D23: Key | E23: 떠오른 잠수함의 밀폐 해치를 여는 열쇠. | F23: 1 | G23: 0 | H23: none | L23: Planning | M23: 히든존 언락(city_02_submarine) | N23: 46209
A24: item_a4_paper | B24: 종이 용지 | C24: Print Paper | D24: Junk | E24: 어디서나 쉽게 볼 수 있는 용지 | F24: 99 | G24: 0 | H24: none | M24: 재료 | N24: 46210
A25: item_banana | B25: 썩은 바나나 | C25: Banana | D25: Food | E25: 건조해져 말라 비틀어진 바나나 | F25: 99 | G25: 0 | H25: heal | J25: 3

Sheet City
A1: CityID | B1: CityName_KR | C1: CityName_EN | D1: DifficultyTier | E1: Theme | F1: Description | G1: UnlockCondition | H1: Status | I1: Notes | J1: LastUpdated
A2: city_01 | B2: 하람 | C2: Haram | D2: 1 | E2: 무너진 위성도시 | F2: 한때 수만 명이 오가던 위성도시. 신호가 끊긴 거리엔 이제 굶주린 것들의 발소리만 울린다. | H2: Planning | I2: 첫 플레이 도시 | J2: 46209
A3: city_02 | B3: 예류 | C3: Yeryu | D3: 2 | E3: 침수된 항만도시 | F3: 바닷물에 반쯤 잠긴 항구. 부패한 습기 아래로, 물에 잠긴 것들이 숨죽여 기다린다. | H3: Planning | I3: - | J3: 46209
A4: city_03 | B4: 강천 | C4: Gangcheon | D4: 3 | E4: 폐쇄된 공업도시 | F4: 기계가 멈추지 않는 버려진 공장지대. 녹슨 쇳덩이와 변이체가 뒤엉켜 도시를 삼켰다. | H4: Planning | I4: - | J4: 46209

Sheet Zone
A1: ZoneID | B1: CityID | C1: ZoneName_KR | D1: ZoneName_EN | E1: Description | F1: LootFocus | G1: IsHidden | H1: UnlockType | I1: UnlockKey | J1: Status | K1: Notes | L1: LastUpdated
A2: city_01_mall | B2: city_01 | C2: 버려진 상가 | D2: Abandoned Mall | E2: 무너진 위성도시의 낡은 쇼핑몰. 먼지 쌓인 진열대에 흔한 물자가 남아있다. | F2: 생필품·의료품 | G2: 0 | H2: always | J2: Planning | K2: - | L2: 46209
A3: city_01_houses | B3: city_01 | C3: 폐가 밀집지 | D3: Abandoned Houses | E3: 버려진 주택들이 늘어선 골목. 조용하지만 방심은 금물이다. | F3: 잡화·기본 재료 | G3: 0 | H3: always | J3: Planning | K3: - | L3: 46209
A4: city_01_tower | B4: city_01 | C4: 녹슨 송신탑 | D4: Rusted Transmission Tower | E4: 도시를 내려다보는 낡은 송신탑. 아직 뜯어낼 전자 부품이 남아있다. | F4: 전자 부품 | G4: 0 | H4: always | J4: Planning | K4: - | L4: 46209
A5: city_01_police | B5: city_01 | C5: 봉쇄된 경찰서 | D5: Sealed Police Station | E5: 비상 셔터로 굳게 잠긴 경찰서. 안에는 손대지 않은 물자가 잠들어 있다. | F5: 무기·탄약·희귀 재료 | G5: 1 | H5: item | I5: item_police_keycard | J5: Planning | K5: 히든 존·아이템 언락 | L5: 46209
A6: city_02_docks | B6: city_02 | C6: 침수된 부두 | D6: Flooded Docks | E6: 바닷물에 잠긴 항구의 부두. 미끄러운 발판 아래로 위험이 도사린다. | F6: 금속·로프 | G6: 0 | H6: always | J6: Planning | K6: - | L6: 46209
A7: city_02_market | B7: city_02 | C7: 버려진 어시장 | D7: Abandoned Fish Market | E7: 썩은 냄새가 진동하는 어시장. 부패한 어둠 속에 물자가 잠겨 있다. | F7: 식재료·부패물 | G7: 0 | H7: always | J7: Planning | K7: - | L7: 46209
A8: city_02_ship | B8: city_02 | C8: 좌초된 화물선 | D8: Grounded Cargo Ship | E8: 해안에 걸린 대형 화물선. 기울어진 선체 안에 값진 화물이 잠들어 있다. | F8: 화물·희귀 재료 | G8: 0 | H8: always | J8: Planning | K8: - | L8: 46209
A9: city_02_submarine | B9: city_02 | C9: 떠오른 잠수함 | D9: Surfaced Submarine | E9: 수면 위로 밀려 올라온 정체불명의 잠수함. 밀폐된 해치 너머는 아무도 본 적이 없다. | F9: 군용 물자·희귀 부품 | G9: 1 | H9: item | I9: item_submarine_key | J9: Planning | K9: 히든 존·아이템 언락 | L9: 46209
A10: city_03_mill | B10: city_03 | C10: 폐쇄된 제철소 | D10: Abandoned Steel Mill | E10: 가동을 멈춘 거대한 제철소. 식지 않은 강철과 위험이 뒤엉켜 있다. | F10: 금속·강철 | G10: 0 | H10: always | J10: Planning | K10: - | L10: 46209
A11: city_03_dump | B11: city_03 | C11: 화학 폐기장 | D11: Chemical Dumpsite | E11: 유독물질이 흘러내리는 폐기장. 변이체가 그 속에서 우글거린다. | F11: 화학물·변이 재료 | G11: 0 | H11: always | J11: Planning | K11: - | L11: 46209
A12: city_03_warehouse | B12: city_03 | C12: 자동화 물류창고 | D12: Automated Warehouse | E12: 여전히 작동하는 경비 기계가 순찰을 도는 창고. 침입자를 반기지 않는다. | F12: 기계 부품 | G12: 0 | H12: always | J12: Planning | K12: - | L12: 46209

Sheet Vendor
A1: VendorID | B1: VendorName_KR | C1: VendorName_EN | D1: ShopType | E1: TradeCategories | F1: ShopID | G1: Description | H1: Status | I1: Notes | J1: LastUpdated
A2: vendor_clinic | B2: 유리 소콜로프 | C2: Yuri Sokolov | D2: Medicine | E2: Medicine | F2: shop_clinic | G2: 보건소를 지키는 전직 군의관. 말수가 적고 손이 정확하다. 약값은 깎아주지 않지만, 위독한 자는 그냥 눕혀준다. | H2: Planning | I2: 보건소 담당 | J2: 46211
A3: vendor_hardware | B3: 딘 카터 | C3: Dean Carter | D3: Junk | E3: Junk | F3: shop_hardware | G3: 철물점의 고물상. 고철 더미 속에서 뭐든 찾아내는 수완가. 농담이 많지만 흥정엔 빈틈이 없다. | H3: Planning | I3: 철물점 담당 | J3: 46211
A4: vendor_canteen | B4: 아미라 하산 | C4: Amira Hassan | D4: Food | E4: Food | F4: shop_canteen | G4: 급식소의 요리사. 배급 식재료로 기적 같은 한 끼를 만든다. 굶주린 자를 그냥 보내지 못하는 정 많은 성격. | H4: Planning | I4: 급식소 담당 | J4: 46211
A5: vendor_blackmarket | B5: 카이토 렌 | C5: Kaito Ren | D5: BlackMarket | E5: Weapon,Armor | F5: shop_blackmarket | G5: 얼굴 절반을 가린 밀매상. 무기와 방어구를 뒷거래한다. 출처는 묻지 않고, 값은 부르는 게 값이다. | H5: Planning | I5: 암시장 담당 | J5: 46211
A6: vendor_pawnshop | B6: 마르타 콜 | C6: Marta Kohl | D6: Pawnshop | E6: Artifact_Worn,Artifact_Carried | F6: shop_pawnshop | G6: 장물과 골동을 감정하는 노회한 전당포 주인. 값진 물건을 알아보는 눈이 매섭다. | H6: Planning | I6: 전당포 담당 | J6: 46212

Sheet Monster
A1: MonsterID | B1: MonsterName_KR | C1: MonsterName_EN | D1: Category | E1: SpawnZones | F1: BaseHP | G1: MinATK | H1: MaxATK | I1: Defense | J1: AttackSpeed | K1: Accuracy | L1: Evasion | M1: CritChance | N1: StatusResist | O1: CritResist | P1: StatusAttack | Q1: Potency | R1: Description | S1: Status | T1: Notes | U1: Grade | V1: StaminaCost | W1: CombatTimeLimit | X1: Material | Y1: LastUpdated
A2: monster_feral_dog | B2: 들개 | C2: Feral Dog | D2: Beast | E2: city_01_mall,city_01_houses | F2: 45 | G2: 5 | H2: 9 | I2: 4 | J2: 1.6 | K2: 6 | L2: 12 | M2: 4 | N2: 5 | O2: 3 | P2: bleed | Q2: 40 | R2: 굶주려 사나워진 들개. 빠르지만 약하다. | S2: Planning | T2: - | U2: Common | V2: =IF($U2="","",SWITCH($U2,"Common",1,"Rare",3,"Unique",6,"Special",10)) -> 1 | W2: =IF($U2="","",SWITCH($U2,"Common",15,"Rare",20,"Unique",30,"Special",60)) -> 15 | X2: - | Y2: 46211
A3: monster_scavenger | B3: 굶주린 부랑자 | C3: Starving Scavenger | D3: Human | E3: city_01_mall,city_01_tower | F3: 65 | G3: 7 | H3: 12 | I3: 8 | J3: 1 | K3: 5 | L3: 6 | M3: 5 | N3: 8 | O3: 4 | P3: bleed | Q3: 30 | R3: 물자를 뒤지는 부랑자. 평범하지만 방심은 금물. | S3: Planning | T3: - | U3: Common | V3: =IF($U3="","",SWITCH($U3,"Common",1,"Rare",3,"Unique",6,"Special",10)) -> 1 | W3: =IF($U3="","",SWITCH($U3,"Common",15,"Rare",20,"Unique",30,"Special",60)) -> 15 | X3: - | Y3: 46211
A4: monster_haram_warden | B4: 하람의 파수꾼 | C4: Warden of Haram | D4: Machine | E4: city_01_tower | F4: 160 | G4: 12 | H4: 18 | I4: 14 | J4: 0.9 | K4: 8 | L4: 5 | M4: 8 | N4: 20 | O4: 10 | P4: stun | Q4: 55 | R4: 송신탑을 지키는 낡은 경비 로봇. | S4: Planning | T4: - | U4: Unique | V4: =IF($U4="","",SWITCH($U4,"Common",1,"Rare",3,"Unique",6,"Special",10)) -> 6 | W4: =IF($U4="","",SWITCH($U4,"Common",15,"Rare",20,"Unique",30,"Special",60)) -> 30 | X4: - | Y4: 46211
A5: monster_mutant_crab | B5: 변이 게 | C5: Mutant Crab | D5: Infected | E5: city_02_docks,city_02_market | F5: 80 | G5: 8 | H5: 13 | I5: 12 | J5: 0.9 | K5: 5 | L5: 5 | M5: 4 | N5: 12 | O5: 5 | P5: pierce | Q5: 45 | R5: 단단한 껍질로 뒤덮인 변이 게. 방어가 높다. | S5: Planning | T5: - | U5: Rare | V5: =IF($U5="","",SWITCH($U5,"Common",1,"Rare",3,"Unique",6,"Special",10)) -> 3 | W5: =IF($U5="","",SWITCH($U5,"Common",15,"Rare",20,"Unique",30,"Special",60)) -> 20 | X5: - | Y5: 46211
A6: monster_drowned | B6: 익사자 | C6: The Drowned | D6: Infected | E6: city_02_docks,city_02_ship | F6: 95 | G6: 9 | H6: 15 | I6: 8 | J6: 1 | K6: 6 | L6: 7 | M6: 5 | N6: 15 | O6: 5 | P6: stun | Q6: 35 | R6: 물에 잠겼다 되살아난 것. 축축하고 끈질기다. | S6: Planning | T6: - | U6: Rare | V6: =IF($U6="","",SWITCH($U6,"Common",1,"Rare",3,"Unique",6,"Special",10)) -> 3 | W6: =IF($U6="","",SWITCH($U6,"Common",15,"Rare",20,"Unique",30,"Special",60)) -> 20 | X6: - | Y6: 46211
A7: monster_yeryu_leviathan | B7: 부두의 거수 | C7: Leviathan of Yeryu | D7: Infected | E7: city_02_ship | F7: 240 | G7: 16 | H7: 24 | I7: 16 | J7: 0.8 | K7: 8 | L7: 4 | M7: 9 | N7: 25 | O7: 12 | P7: rupture | Q7: 60 | R7: 화물선에 자리 잡은 거대한 변이체. | S7: Planning | T7: - | U7: Special | V7: =IF($U7="","",SWITCH($U7,"Common",1,"Rare",3,"Unique",6,"Special",10)) -> 10 | W7: =IF($U7="","",SWITCH($U7,"Common",15,"Rare",20,"Unique",30,"Special",60)) -> 60 | X7: - | Y7: 46211
A8: monster_rogue_drone | B8: 폭주 드론 | C8: Rogue Drone | D8: Machine | E8: city_03_mill,city_03_warehouse | F8: 110 | G8: 11 | H8: 17 | I8: 18 | J8: 1.1 | K8: 9 | L8: 6 | M8: 7 | N8: 20 | O8: 8 | P8: pierce | Q8: 45 | R8: 통제를 잃고 공격하는 순찰 드론. 장갑이 두껍다. | S8: Planning | T8: - | U8: Rare | V8: =IF($U8="","",SWITCH($U8,"Common",1,"Rare",3,"Unique",6,"Special",10)) -> 3 | W8: =IF($U8="","",SWITCH($U8,"Common",15,"Rare",20,"Unique",30,"Special",60)) -> 20 | X8: - | Y8: 46211
A9: monster_chem_horror | B9: 화학 변이체 | C9: Chemical Horror | D9: Infected | E9: city_03_dump | F9: 140 | G9: 12 | H9: 19 | I9: 12 | J9: 0.8 | K9: 6 | L9: 4 | M9: 6 | N9: 30 | O9: 6 | P9: bleed | Q9: 55 | R9: 유독물질에 뒤틀린 살덩이. 느리지만 끈질기다. | S9: Planning | T9: - | U9: Unique | V9: =IF($U9="","",SWITCH($U9,"Common",1,"Rare",3,"Unique",6,"Special",10)) -> 6 | W9: =IF($U9="","",SWITCH($U9,"Common",15,"Rare",20,"Unique",30,"Special",60)) -> 30 | X9: - | Y9: 46211
A10: monster_gangcheon_golem | B10: 폐기물 골렘 | C10: Scrap Golem of Gangcheon | D10: Machine | E10: city_03_mill | F10: 320 | G10: 20 | H10: 30 | I10: 24 | J10: 0.7 | K10: 9 | L10: 3 | M10: 10 | N10: 35 | O10: 15 | P10: rupture | Q10: 65 | R10: 고철이 뭉쳐 만들어진 거대 골렘. | S10: Planning | T10: - | U10: Special | V10: =IF($U10="","",SWITCH($U10,"Common",1,"Rare",3,"Unique",6,"Special",10)) -> 10 | W10: =IF($U10="","",SWITCH($U10,"Common",15,"Rare",20,"Unique",30,"Special",60)) -> 60 | X10: - | Y10: 46211
A11: monster_rogue_alley | B11: 골목길 불량배 | C11: Alley Thug | D11: Human | E11: city_01_mall,city_01_houses | F11: 60 | G11: 5 | H11: 11 | I11: 3 | J11: 1.2 | K11: 8 | L11: 5 | M11: 5 | N11: 10 | O11: 4 | P11: bleed | Q11: 30 | R11: 골목을 배회하는 불량배. 약하지만 재빠르다. | S11: Planning | T11: - | U11: Common | V11: =IF($U11="","",SWITCH($U11,"Common",1,"Rare",3,"Unique",6,"Special",10)) -> 1 | W11: =IF($U11="","",SWITCH($U11,"Common",15,"Rare",20,"Unique",30,"Special",60)) -> 15 | X11: - | Y11: 46211

Sheet Weapon
A1: WeaponID | B1: WeaponName_KR | C1: WeaponName_EN | D1: Category | E1: Attribute | F1: Material | G1: MinAtk_Low | H1: MinAtk_High | I1: MaxAtk_Low | J1: MaxAtk_High | K1: AttackSpeed | L1: Accuracy | M1: CritChance | N1: MaxDurability | O1: DropRate | P1: PrefixGroups | Q1: SuffixGroups | R1: Potency | S1: GrowthTag_Str | T1: GrowthTag_Dex | U1: GrowthTag_Vit | V1: GrowthTag_Will | W1: Status | X1: Notes | Y1: LastUpdated
A2: weapon_iron_pipe | B2: 쇠파이프 | C2: Iron Pipe | D2: Weapon | E2: stun | F2: 금속 | G2: 3 | H2: 5 | I2: 6 | J2: 10 | K2: 1 | L2: 4 | M2: 3 | N2: 40 | O2: 12 | P2: wea1 | Q2: wea1 | R2: 55 | S2: 1 | T2: 0 | U2: 0 | V2: 0 | W2: Planning | X2: 기절 | Y2: 46210
A3: weapon_wooden_sword | B3: 목검 | C3: Wooden Sword | D3: Weapon | E3: bleed | F3: 목재 | G3: 1 | H3: 3 | I3: 3 | J3: 6 | K3: 1.3 | L3: 3 | M3: 2 | N3: 30 | O3: 15 | P3: wea1 | Q3: wea1 | R3: 35 | S3: 0 | T3: 1 | U3: 0 | V3: 0 | W3: Planning | X3: 약한 출혈·기본 무기 | Y3: 46210
A4: weapon_spear | B4: 장창 | C4: Spear | D4: Weapon | E4: pierce | F4: 금속 | G4: 6 | H4: 9 | I4: 12 | J4: 18 | K4: 0.9 | L4: 3 | M4: 5 | N4: 50 | O4: 6 | P4: wea1,wea2 | Q4: wea1 | R4: 45 | S4: 0 | T4: 1 | U4: 0 | V4: 0 | W4: Planning | X4: 관통 | Y4: 46210
A5: weapon_sledgehammer | B5: 대형 해머 | C5: Sledgehammer | D5: Weapon | E5: rupture | F5: 금속 | G5: 8 | H5: 12 | I5: 16 | J5: 24 | K5: 0.7 | L5: 2 | M5: 4 | N5: 55 | O5: 4 | P5: wea1 | Q5: wea1 | R5: 65 | S5: 1 | T5: 0 | U5: 1 | V5: 0 | W5: Planning | X5: 파열 | Y5: 46210
A6: weapon_hatchet | B6: 손도끼 | C6: Hatchet | D6: Weapon | E6: bleed | F6: 금속 | G6: 4 | H6: 6 | I6: 8 | J6: 12 | K6: 1.1 | L6: 5 | M6: 4 | N6: 45 | O6: 9 | P6: wea2 | Q6: wea1,wea2 | R6: 50 | S6: 1 | T6: 0 | U6: 0 | V6: 0 | W6: Planning | X6: 베기·치명타형 | Y6: 46210

Sheet Armor
A1: ArmorID | B1: ArmorName_KR | C1: ArmorName_EN | D1: Category | E1: Material | F1: Def_Low | G1: Def_High | H1: Evasion | I1: StatusResist | J1: MaxDurability | K1: DropRate | L1: PrefixGroups | M1: SuffixGroups | N1: GrowthTag_Str | O1: GrowthTag_Dex | P1: GrowthTag_Vit | Q1: GrowthTag_Will | R1: Status | S1: Notes | T1: LastUpdated
A2: armor_cloth_hood | B2: 천 후드 | C2: Cloth Hood | D2: Head | E2: 섬유 | F2: 1 | G2: 3 | H2: 4 | I2: 8 | J2: 35 | K2: 14 | L2: arm1,arm4 | M2: arm3,arm4 | N2: 0 | O2: 1 | P2: 0 | Q2: 0 | R2: Planning | S2: 가벼움·회피형 | T2: 46210
A3: armor_steel_helmet | B3: 철제 투구 | C3: Steel Helmet | D3: Head | E3: 금속 | F3: 3 | G3: 6 | H3: 1 | I3: 15 | J3: 60 | K3: 8 | L3: arm2,arm3 | M3: arm3,arm4 | N3: 0 | O3: 0 | P3: 1 | Q3: 0 | R3: Planning | S3: 방어형·무거움 | T3: 46210
A4: armor_leather_jacket | B4: 가죽 재킷 | C4: Leather Jacket | D4: Body | E4: 합성 | F4: 4 | G4: 8 | H4: 3 | I4: 20 | J4: 60 | K4: 12 | L4: arm1,arm2 | M4: arm1,arm4 | N4: 0 | O4: 0 | P4: 1 | Q4: 0 | R4: Planning | S4: 균형형 | T4: 46210
A5: armor_steel_plate | B5: 철제 갑옷 | C5: Steel Plate | D5: Body | E5: 금속 | F5: 7 | G5: 13 | H5: 1 | I5: 25 | J5: 90 | K5: 6 | L5: arm1,arm2 | M5: arm1,arm4 | N5: 0 | O5: 0 | P5: 1 | Q5: 0 | R5: Planning | S5: 방어형·무거움 | T5: 46210

Sheet All_IDs
A1: =IFERROR(__xludf.DUMMYFUNCTION("{ ""ItemID"",""이름(KR)"",""이름(EN)"",""Category""; QUERY({Item!A2:D3498; Weapon!A2:D3498; Armor!A2:D3498; Artifact!A2:D3498}, ""select * where Col1 is not null"", 0) }"),"ItemID") -> ItemID | B1: =IFERROR(__xludf.DUMMYFUNCTION("""COMPUTED_VALUE"""),"이름(KR)") -> 이름(KR) | C1: =IFERROR(__xludf.DUMMYFUNCTION("""COMPUTED_VALUE"""),"이름(EN)") -> 이름(EN) | D1: =IFERROR(__xludf.DUMMYFUNCTION("""COMPUTED_VALUE"""),"Category") -> Category
A2: =IFERROR(__xludf.DUMMYFUNCTION("""COMPUTED_VALUE"""),"item_scrap_metal") -> item_scrap_metal | B2: =IFERROR(__xludf.DUMMYFUNCTION("""COMPUTED_VALUE"""),"고철") -> 고철 | C2: =IFERROR(__xludf.DUMMYFUNCTION("""COMPUTED_VALUE"""),"Scrap Metal") -> Scrap Metal | D2: =IFERROR(__xludf.DUMMYFUNCTION("""COMPUTED_VALUE"""),"Junk") -> Junk
A3: =IFERROR(__xludf.DUMMYFUNCTION("""COMPUTED_VALUE"""),"item_electronic_parts") -> item_electronic_parts | B3: =IFERROR(__xludf.DUMMYFUNCTION("""COMPUTED_VALUE"""),"전자 부품") -> 전자 부품 | C3: =IFERROR(__xludf.DUMMYFUNCTION("""COMPUTED_VALUE"""),"Electronic Parts") -> Electronic Parts | D3: =IFERROR(__xludf.DUMMYFUNCTION("""COMPUTED_VALUE"""),"Junk") -> Junk
A4: =IFERROR(__xludf.DUMMYFUNCTION("""COMPUTED_VALUE"""),"item_machine_parts") -> item_machine_parts | B4: =IFERROR(__xludf.DUMMYFUNCTION("""COMPUTED_VALUE"""),"기계 부품") -> 기계 부품 | C4: =IFERROR(__xludf.DUMMYFUNCTION("""COMPUTED_VALUE"""),"Machine Parts") -> Machine Parts | D4: =IFERROR(__xludf.DUMMYFUNCTION("""COMPUTED_VALUE"""),"Junk") -> Junk
A5: =IFERROR(__xludf.DUMMYFUNCTION("""COMPUTED_VALUE"""),"item_mutant_tissue") -> item_mutant_tissue | B5: =IFERROR(__xludf.DUMMYFUNCTION("""COMPUTED_VALUE"""),"변이 조직") -> 변이 조직 | C5: =IFERROR(__xludf.DUMMYFUNCTION("""COMPUTED_VALUE"""),"Mutant Tissue") -> Mutant Tissue | D5: =IFERROR(__xludf.DUMMYFUNCTION("""COMPUTED_VALUE"""),"Junk") -> Junk
A6: =IFERROR(__xludf.DUMMYFUNCTION("""COMPUTED_VALUE"""),"item_old_rope") -> item_old_rope | B6: =IFERROR(__xludf.DUMMYFUNCTION("""COMPUTED_VALUE"""),"낡은 로프") -> 낡은 로프 | C6: =IFERROR(__xludf.DUMMYFUNCTION("""COMPUTED_VALUE"""),"Old Rope") -> Old Rope | D6: =IFERROR(__xludf.DUMMYFUNCTION("""COMPUTED_VALUE"""),"Junk") -> Junk
A7: =IFERROR(__xludf.DUMMYFUNCTION("""COMPUTED_VALUE"""),"item_food_coffee") -> item_food_coffee | B7: =IFERROR(__xludf.DUMMYFUNCTION("""COMPUTED_VALUE"""),"원두 한 줌") -> 원두 한 줌 | C7: =IFERROR(__xludf.DUMMYFUNCTION("""COMPUTED_VALUE"""),"Handful of Coffee Beans") -> Handful of Coffee Beans | D7: =IFERROR(__xludf.DUMMYFUNCTION("""COMPUTED_VALUE"""),"Food") -> Food
A8: =IFERROR(__xludf.DUMMYFUNCTION("""COMPUTED_VALUE"""),"item_food_jerky") -> item_food_jerky | B8: =IFERROR(__xludf.DUMMYFUNCTION("""COMPUTED_VALUE"""),"훈제육") -> 훈제육 | C8: =IFERROR(__xludf.DUMMYFUNCTION("""COMPUTED_VALUE"""),"Smoked Jerky") -> Smoked Jerky | D8: =IFERROR(__xludf.DUMMYFUNCTION("""COMPUTED_VALUE"""),"Food") -> Food
A9: =IFERROR(__xludf.DUMMYFUNCTION("""COMPUTED_VALUE"""),"item_food_stew") -> item_food_stew | B9: =IFERROR(__xludf.DUMMYFUNCTION("""COMPUTED_VALUE"""),"영양 스튜") -> 영양 스튜 | C9: =IFERROR(__xludf.DUMMYFUNCTION("""COMPUTED_VALUE"""),"Nourishing Stew") -> Nourishing Stew | D9: =IFERROR(__xludf.DUMMYFUNCTION("""COMPUTED_VALUE"""),"Food") -> Food
A10: =IFERROR(__xludf.DUMMYFUNCTION("""COMPUTED_VALUE"""),"item_food_canfruit") -> item_food_canfruit | B10: =IFERROR(__xludf.DUMMYFUNCTION("""COMPUTED_VALUE"""),"통조림 과일") -> 통조림 과일 | C10: =IFERROR(__xludf.DUMMYFUNCTION("""COMPUTED_VALUE"""),"Canned Fruit") -> Canned Fruit | D10: =IFERROR(__xludf.DUMMYFUNCTION("""COMPUTED_VALUE"""),"Food") -> Food
A11: =IFERROR(__xludf.DUMMYFUNCTION("""COMPUTED_VALUE"""),"item_food_energybar") -> item_food_energybar | B11: =IFERROR(__xludf.DUMMYFUNCTION("""COMPUTED_VALUE"""),"비상 식량바") -> 비상 식량바 | C11: =IFERROR(__xludf.DUMMYFUNCTION("""COMPUTED_VALUE"""),"Emergency Ration Bar") -> Emergency Ration Bar | D11: =IFERROR(__xludf.DUMMYFUNCTION("""COMPUTED_VALUE"""),"Food") -> Food
A12: =IFERROR(__xludf.DUMMYFUNCTION("""COMPUTED_VALUE"""),"item_med_bandage") -> item_med_bandage | B12: =IFERROR(__xludf.DUMMYFUNCTION("""COMPUTED_VALUE"""),"붕대") -> 붕대 | C12: =IFERROR(__xludf.DUMMYFUNCTION("""COMPUTED_VALUE"""),"Bandage") -> Bandage | D12: =IFERROR(__xludf.DUMMYFUNCTION("""COMPUTED_VALUE"""),"Medicine") -> Medicine
A13: =IFERROR(__xludf.DUMMYFUNCTION("""COMPUTED_VALUE"""),"item_med_kit") -> item_med_kit | B13: =IFERROR(__xludf.DUMMYFUNCTION("""COMPUTED_VALUE"""),"응급 키트") -> 응급 키트 | C13: =IFERROR(__xludf.DUMMYFUNCTION("""COMPUTED_VALUE"""),"First-aid Kit") -> First-aid Kit | D13: =IFERROR(__xludf.DUMMYFUNCTION("""COMPUTED_VALUE"""),"Medicine") -> Medicine
A14: =IFERROR(__xludf.DUMMYFUNCTION("""COMPUTED_VALUE"""),"item_med_syringe") -> item_med_syringe | B14: =IFERROR(__xludf.DUMMYFUNCTION("""COMPUTED_VALUE"""),"지혈 주사기") -> 지혈 주사기 | C14: =IFERROR(__xludf.DUMMYFUNCTION("""COMPUTED_VALUE"""),"Hemostatic Syringe") -> Hemostatic Syringe | D14: =IFERROR(__xludf.DUMMYFUNCTION("""COMPUTED_VALUE"""),"Medicine") -> Medicine
A15: =IFERROR(__xludf.DUMMYFUNCTION("""COMPUTED_VALUE"""),"item_med_painkiller") -> item_med_painkiller | B15: =IFERROR(__xludf.DUMMYFUNCTION("""COMPUTED_VALUE"""),"진통제") -> 진통제 | C15: =IFERROR(__xludf.DUMMYFUNCTION("""COMPUTED_VALUE"""),"Painkiller") -> Painkiller | D15: =IFERROR(__xludf.DUMMYFUNCTION("""COMPUTED_VALUE"""),"Medicine") -> Medicine
A16: =IFERROR(__xludf.DUMMYFUNCTION("""COMPUTED_VALUE"""),"item_med_antidote") -> item_med_antidote | B16: =IFERROR(__xludf.DUMMYFUNCTION("""COMPUTED_VALUE"""),"해독제") -> 해독제 | C16: =IFERROR(__xludf.DUMMYFUNCTION("""COMPUTED_VALUE"""),"Antidote") -> Antidote | D16: =IFERROR(__xludf.DUMMYFUNCTION("""COMPUTED_VALUE"""),"Medicine") -> Medicine
A17: =IFERROR(__xludf.DUMMYFUNCTION("""COMPUTED_VALUE"""),"item_quest_photo") -> item_quest_photo | B17: =IFERROR(__xludf.DUMMYFUNCTION("""COMPUTED_VALUE"""),"낡은 사진") -> 낡은 사진 | C17: =IFERROR(__xludf.DUMMYFUNCTION("""COMPUTED_VALUE"""),"Old Photograph") -> Old Photograph | D17: =IFERROR(__xludf.DUMMYFUNCTION("""COMPUTED_VALUE"""),"Quest") -> Quest
A18: =IFERROR(__xludf.DUMMYFUNCTION("""COMPUTED_VALUE"""),"item_quest_dogtag") -> item_quest_dogtag | B18: =IFERROR(__xludf.DUMMYFUNCTION("""COMPUTED_VALUE"""),"낡은 군번줄") -> 낡은 군번줄 | C18: =IFERROR(__xludf.DUMMYFUNCTION("""COMPUTED_VALUE"""),"Worn Dog Tag") -> Worn Dog Tag | D18: =IFERROR(__xludf.DUMMYFUNCTION("""COMPUTED_VALUE"""),"Quest") -> Quest
A19: =IFERROR(__xludf.DUMMYFUNCTION("""COMPUTED_VALUE"""),"item_quest_letter") -> item_quest_letter | B19: =IFERROR(__xludf.DUMMYFUNCTION("""COMPUTED_VALUE"""),"봉인된 편지") -> 봉인된 편지 | C19: =IFERROR(__xludf.DUMMYFUNCTION("""COMPUTED_VALUE"""),"Sealed Letter") -> Sealed Letter | D19: =IFERROR(__xludf.DUMMYFUNCTION("""COMPUTED_VALUE"""),"Quest") -> Quest
A20: =IFERROR(__xludf.DUMMYFUNCTION("""COMPUTED_VALUE"""),"item_quest_keydata") -> item_quest_keydata | B20: =IFERROR(__xludf.DUMMYFUNCTION("""COMPUTED_VALUE"""),"손상된 USB") -> 손상된 USB | C20: =IFERROR(__xludf.DUMMYFUNCTION("""COMPUTED_VALUE"""),"Damaged USB") -> Damaged USB | D20: =IFERROR(__xludf.DUMMYFUNCTION("""COMPUTED_VALUE"""),"Quest") -> Quest
A21: =IFERROR(__xludf.DUMMYFUNCTION("""COMPUTED_VALUE"""),"item_quest_medallion") -> item_quest_medallion | B21: =IFERROR(__xludf.DUMMYFUNCTION("""COMPUTED_VALUE"""),"빛바랜 훈장") -> 빛바랜 훈장 | C21: =IFERROR(__xludf.DUMMYFUNCTION("""COMPUTED_VALUE"""),"Faded Medallion") -> Faded Medallion | D21: =IFERROR(__xludf.DUMMYFUNCTION("""COMPUTED_VALUE"""),"Quest") -> Quest
A22: =IFERROR(__xludf.DUMMYFUNCTION("""COMPUTED_VALUE"""),"item_police_keycard") -> item_police_keycard | B22: =IFERROR(__xludf.DUMMYFUNCTION("""COMPUTED_VALUE"""),"경찰서 키카드") -> 경찰서 키카드 | C22: =IFERROR(__xludf.DUMMYFUNCTION("""COMPUTED_VALUE"""),"Police Keycard") -> Police Keycard | D22: =IFERROR(__xludf.DUMMYFUNCTION("""COMPUTED_VALUE"""),"Key") -> Key
A23: =IFERROR(__xludf.DUMMYFUNCTION("""COMPUTED_VALUE"""),"item_submarine_key") -> item_submarine_key | B23: =IFERROR(__xludf.DUMMYFUNCTION("""COMPUTED_VALUE"""),"잠수함 해치 키") -> 잠수함 해치 키 | C23: =IFERROR(__xludf.DUMMYFUNCTION("""COMPUTED_VALUE"""),"Submarine Hatch Key") -> Submarine Hatch Key | D23: =IFERROR(__xludf.DUMMYFUNCTION("""COMPUTED_VALUE"""),"Key") -> Key
A24: =IFERROR(__xludf.DUMMYFUNCTION("""COMPUTED_VALUE"""),"item_a4_paper") -> item_a4_paper | B24: =IFERROR(__xludf.DUMMYFUNCTION("""COMPUTED_VALUE"""),"종이 용지") -> 종이 용지 | C24: =IFERROR(__xludf.DUMMYFUNCTION("""COMPUTED_VALUE"""),"Print Paper") -> Print Paper | D24: =IFERROR(__xludf.DUMMYFUNCTION("""COMPUTED_VALUE"""),"Junk") -> Junk
A25: =IFERROR(__xludf.DUMMYFUNCTION("""COMPUTED_VALUE"""),"item_banana") -> item_banana | B25: =IFERROR(__xludf.DUMMYFUNCTION("""COMPUTED_VALUE"""),"썩은 바나나") -> 썩은 바나나 | C25: =IFERROR(__xludf.DUMMYFUNCTION("""COMPUTED_VALUE"""),"Banana") -> Banana | D25: =IFERROR(__xludf.DUMMYFUNCTION("""COMPUTED_VALUE"""),"Food") -> Food
A26: =IFERROR(__xludf.DUMMYFUNCTION("""COMPUTED_VALUE"""),"weapon_iron_pipe") -> weapon_iron_pipe | B26: =IFERROR(__xludf.DUMMYFUNCTION("""COMPUTED_VALUE"""),"쇠파이프") -> 쇠파이프 | C26: =IFERROR(__xludf.DUMMYFUNCTION("""COMPUTED_VALUE"""),"Iron Pipe") -> Iron Pipe | D26: =IFERROR(__xludf.DUMMYFUNCTION("""COMPUTED_VALUE"""),"Weapon") -> Weapon
A27: =IFERROR(__xludf.DUMMYFUNCTION("""COMPUTED_VALUE"""),"weapon_wooden_sword") -> weapon_wooden_sword | B27: =IFERROR(__xludf.DUMMYFUNCTION("""COMPUTED_VALUE"""),"목검") -> 목검 | C27: =IFERROR(__xludf.DUMMYFUNCTION("""COMPUTED_VALUE"""),"Wooden Sword") -> Wooden Sword | D27: =IFERROR(__xludf.DUMMYFUNCTION("""COMPUTED_VALUE"""),"Weapon") -> Weapon
A28: =IFERROR(__xludf.DUMMYFUNCTION("""COMPUTED_VALUE"""),"weapon_spear") -> weapon_spear | B28: =IFERROR(__xludf.DUMMYFUNCTION("""COMPUTED_VALUE"""),"장창") -> 장창 | C28: =IFERROR(__xludf.DUMMYFUNCTION("""COMPUTED_VALUE"""),"Spear") -> Spear | D28: =IFERROR(__xludf.DUMMYFUNCTION("""COMPUTED_VALUE"""),"Weapon") -> Weapon
A29: =IFERROR(__xludf.DUMMYFUNCTION("""COMPUTED_VALUE"""),"weapon_sledgehammer") -> weapon_sledgehammer | B29: =IFERROR(__xludf.DUMMYFUNCTION("""COMPUTED_VALUE"""),"대형 해머") -> 대형 해머 | C29: =IFERROR(__xludf.DUMMYFUNCTION("""COMPUTED_VALUE"""),"Sledgehammer") -> Sledgehammer | D29: =IFERROR(__xludf.DUMMYFUNCTION("""COMPUTED_VALUE"""),"Weapon") -> Weapon
A30: =IFERROR(__xludf.DUMMYFUNCTION("""COMPUTED_VALUE"""),"weapon_hatchet") -> weapon_hatchet | B30: =IFERROR(__xludf.DUMMYFUNCTION("""COMPUTED_VALUE"""),"손도끼") -> 손도끼 | C30: =IFERROR(__xludf.DUMMYFUNCTION("""COMPUTED_VALUE"""),"Hatchet") -> Hatchet | D30: =IFERROR(__xludf.DUMMYFUNCTION("""COMPUTED_VALUE"""),"Weapon") -> Weapon
A31: =IFERROR(__xludf.DUMMYFUNCTION("""COMPUTED_VALUE"""),"armor_cloth_hood") -> armor_cloth_hood | B31: =IFERROR(__xludf.DUMMYFUNCTION("""COMPUTED_VALUE"""),"천 후드") -> 천 후드 | C31: =IFERROR(__xludf.DUMMYFUNCTION("""COMPUTED_VALUE"""),"Cloth Hood") -> Cloth Hood | D31: =IFERROR(__xludf.DUMMYFUNCTION("""COMPUTED_VALUE"""),"Head") -> Head
A32: =IFERROR(__xludf.DUMMYFUNCTION("""COMPUTED_VALUE"""),"armor_steel_helmet") -> armor_steel_helmet | B32: =IFERROR(__xludf.DUMMYFUNCTION("""COMPUTED_VALUE"""),"철제 투구") -> 철제 투구 | C32: =IFERROR(__xludf.DUMMYFUNCTION("""COMPUTED_VALUE"""),"Steel Helmet") -> Steel Helmet | D32: =IFERROR(__xludf.DUMMYFUNCTION("""COMPUTED_VALUE"""),"Head") -> Head
A33: =IFERROR(__xludf.DUMMYFUNCTION("""COMPUTED_VALUE"""),"armor_leather_jacket") -> armor_leather_jacket | B33: =IFERROR(__xludf.DUMMYFUNCTION("""COMPUTED_VALUE"""),"가죽 재킷") -> 가죽 재킷 | C33: =IFERROR(__xludf.DUMMYFUNCTION("""COMPUTED_VALUE"""),"Leather Jacket") -> Leather Jacket | D33: =IFERROR(__xludf.DUMMYFUNCTION("""COMPUTED_VALUE"""),"Body") -> Body
A34: =IFERROR(__xludf.DUMMYFUNCTION("""COMPUTED_VALUE"""),"armor_steel_plate") -> armor_steel_plate | B34: =IFERROR(__xludf.DUMMYFUNCTION("""COMPUTED_VALUE"""),"철제 갑옷") -> 철제 갑옷 | C34: =IFERROR(__xludf.DUMMYFUNCTION("""COMPUTED_VALUE"""),"Steel Plate") -> Steel Plate | D34: =IFERROR(__xludf.DUMMYFUNCTION("""COMPUTED_VALUE"""),"Body") -> Body
A35: =IFERROR(__xludf.DUMMYFUNCTION("""COMPUTED_VALUE"""),"art_watch_worn") -> art_watch_worn | B35: =IFERROR(__xludf.DUMMYFUNCTION("""COMPUTED_VALUE"""),"낡은 손목시계") -> 낡은 손목시계 | C35: =IFERROR(__xludf.DUMMYFUNCTION("""COMPUTED_VALUE"""),"Worn Wristwatch") -> Worn Wristwatch | D35: =IFERROR(__xludf.DUMMYFUNCTION("""COMPUTED_VALUE"""),"Artifact_Worn") -> Artifact_Worn
A36: =IFERROR(__xludf.DUMMYFUNCTION("""COMPUTED_VALUE"""),"art_ring_iron") -> art_ring_iron | B36: =IFERROR(__xludf.DUMMYFUNCTION("""COMPUTED_VALUE"""),"무쇠 반지") -> 무쇠 반지 | C36: =IFERROR(__xludf.DUMMYFUNCTION("""COMPUTED_VALUE"""),"Iron Ring") -> Iron Ring | D36: =IFERROR(__xludf.DUMMYFUNCTION("""COMPUTED_VALUE"""),"Artifact_Worn") -> Artifact_Worn
A37: =IFERROR(__xludf.DUMMYFUNCTION("""COMPUTED_VALUE"""),"art_necklace_old") -> art_necklace_old | B37: =IFERROR(__xludf.DUMMYFUNCTION("""COMPUTED_VALUE"""),"오래된 목걸이") -> 오래된 목걸이 | C37: =IFERROR(__xludf.DUMMYFUNCTION("""COMPUTED_VALUE"""),"Old Necklace") -> Old Necklace | D37: =IFERROR(__xludf.DUMMYFUNCTION("""COMPUTED_VALUE"""),"Artifact_Worn") -> Artifact_Worn
A38: =IFERROR(__xludf.DUMMYFUNCTION("""COMPUTED_VALUE"""),"art_shoes_worn") -> art_shoes_worn | B38: =IFERROR(__xludf.DUMMYFUNCTION("""COMPUTED_VALUE"""),"낡은 운동화") -> 낡은 운동화 | C38: =IFERROR(__xludf.DUMMYFUNCTION("""COMPUTED_VALUE"""),"Worn Sneakers") -> Worn Sneakers | D38: =IFERROR(__xludf.DUMMYFUNCTION("""COMPUTED_VALUE"""),"Artifact_Worn") -> Artifact_Worn
A39: =IFERROR(__xludf.DUMMYFUNCTION("""COMPUTED_VALUE"""),"art_boots_heavy") -> art_boots_heavy | B39: =IFERROR(__xludf.DUMMYFUNCTION("""COMPUTED_VALUE"""),"무거운 군화") -> 무거운 군화 | C39: =IFERROR(__xludf.DUMMYFUNCTION("""COMPUTED_VALUE"""),"Heavy Combat Boots") -> Heavy Combat Boots | D39: =IFERROR(__xludf.DUMMYFUNCTION("""COMPUTED_VALUE"""),"Artifact_Worn") -> Artifact_Worn
A40: =IFERROR(__xludf.DUMMYFUNCTION("""COMPUTED_VALUE"""),"art_charm_paper") -> art_charm_paper | B40: =IFERROR(__xludf.DUMMYFUNCTION("""COMPUTED_VALUE"""),"종이 부적") -> 종이 부적 | C40: =IFERROR(__xludf.DUMMYFUNCTION("""COMPUTED_VALUE"""),"Paper Charm") -> Paper Charm | D40: =IFERROR(__xludf.DUMMYFUNCTION("""COMPUTED_VALUE"""),"Artifact_Carried") -> Artifact_Carried
...

Sheet LootTable
A1: LootID | B1: MonsterName_KR | C1: MonsterName_EN | D1: MonsterID | E1: ItemName_KR | F1: ItemName_EN | G1: ItemID | H1: Category | I1: DropRate | J1: MinQty | K1: MaxQty
A2: =IF($B2="","",N(A1)+1) -> 1 | B2: 들개 | C2: {=IF($B2="","",IFERROR(XLOOKUP($B2,Monster!$B:$B,Monster!$C:$C),""))} -> Feral Dog | D2: {=IF($B2="","",IFERROR(XLOOKUP($B2,Monster!$B:$B,Monster!$A:$A),""))} -> monster_feral_dog | E2: 낡은 로프 | F2: {=IF($E2="","",IFERROR(XLOOKUP($E2,All_IDs!$B:$B,All_IDs!$C:$C),""))} -> Old Rope | G2: {=IF($E2="","",IFERROR(XLOOKUP($E2,All_IDs!$B:$B,All_IDs!$A:$A),""))} -> item_old_rope | H2: {=IF($E2="","",IFERROR(XLOOKUP($E2,All_IDs!$B:$B,All_IDs!$D:$D),""))} -> Junk | I2: 20 | J2: 1 | K2: 1
A3: =IF($B3="","",N(A2)+1) -> 2 | B3: 들개 | C3: {=IF($B3="","",IFERROR(XLOOKUP($B3,Monster!$B:$B,Monster!$C:$C),""))} -> Feral Dog | D3: {=IF($B3="","",IFERROR(XLOOKUP($B3,Monster!$B:$B,Monster!$A:$A),""))} -> monster_feral_dog | E3: 훈제육 | F3: {=IF($E3="","",IFERROR(XLOOKUP($E3,All_IDs!$B:$B,All_IDs!$C:$C),""))} -> Smoked Jerky | G3: {=IF($E3="","",IFERROR(XLOOKUP($E3,All_IDs!$B:$B,All_IDs!$A:$A),""))} -> item_food_jerky | H3: {=IF($E3="","",IFERROR(XLOOKUP($E3,All_IDs!$B:$B,All_IDs!$D:$D),""))} -> Food | I3: 30 | J3: 1 | K3: 1
A4: =IF($B4="","",N(A3)+1) -> 3 | B4: 들개 | C4: {=IF($B4="","",IFERROR(XLOOKUP($B4,Monster!$B:$B,Monster!$C:$C),""))} -> Feral Dog | D4: {=IF($B4="","",IFERROR(XLOOKUP($B4,Monster!$B:$B,Monster!$A:$A),""))} -> monster_feral_dog | E4: 고철 | F4: {=IF($E4="","",IFERROR(XLOOKUP($E4,All_IDs!$B:$B,All_IDs!$C:$C),""))} -> Scrap Metal | G4: {=IF($E4="","",IFERROR(XLOOKUP($E4,All_IDs!$B:$B,All_IDs!$A:$A),""))} -> item_scrap_metal | H4: {=IF($E4="","",IFERROR(XLOOKUP($E4,All_IDs!$B:$B,All_IDs!$D:$D),""))} -> Junk | I4: 10 | J4: 1 | K4: 1
A5: =IF($B5="","",N(A4)+1) -> 4 | B5: 굶주린 부랑자 | C5: {=IF($B5="","",IFERROR(XLOOKUP($B5,Monster!$B:$B,Monster!$C:$C),""))} -> Starving Scavenger | D5: {=IF($B5="","",IFERROR(XLOOKUP($B5,Monster!$B:$B,Monster!$A:$A),""))} -> monster_scavenger | E5: 지혈 주사기 | F5: {=IF($E5="","",IFERROR(XLOOKUP($E5,All_IDs!$B:$B,All_IDs!$C:$C),""))} -> Hemostatic Syringe | G5: {=IF($E5="","",IFERROR(XLOOKUP($E5,All_IDs!$B:$B,All_IDs!$A:$A),""))} -> item_med_syringe | H5: {=IF($E5="","",IFERROR(XLOOKUP($E5,All_IDs!$B:$B,All_IDs!$D:$D),""))} -> Medicine | I5: 5 | J5: 1 | K5: 1
A6: =IF($B6="","",N(A5)+1) -> 5 | B6: 굶주린 부랑자 | C6: {=IF($B6="","",IFERROR(XLOOKUP($B6,Monster!$B:$B,Monster!$C:$C),""))} -> Starving Scavenger | D6: {=IF($B6="","",IFERROR(XLOOKUP($B6,Monster!$B:$B,Monster!$A:$A),""))} -> monster_scavenger | E6: 붕대 | F6: {=IF($E6="","",IFERROR(XLOOKUP($E6,All_IDs!$B:$B,All_IDs!$C:$C),""))} -> Bandage | G6: {=IF($E6="","",IFERROR(XLOOKUP($E6,All_IDs!$B:$B,All_IDs!$A:$A),""))} -> item_med_bandage | H6: {=IF($E6="","",IFERROR(XLOOKUP($E6,All_IDs!$B:$B,All_IDs!$D:$D),""))} -> Medicine | I6: 5 | J6: 1 | K6: 1
A7: =IF($B7="","",N(A6)+1) -> 6 | B7: 굶주린 부랑자 | C7: {=IF($B7="","",IFERROR(XLOOKUP($B7,Monster!$B:$B,Monster!$C:$C),""))} -> Starving Scavenger | D7: {=IF($B7="","",IFERROR(XLOOKUP($B7,Monster!$B:$B,Monster!$A:$A),""))} -> monster_scavenger | E7: 고철 | F7: {=IF($E7="","",IFERROR(XLOOKUP($E7,All_IDs!$B:$B,All_IDs!$C:$C),""))} -> Scrap Metal | G7: {=IF($E7="","",IFERROR(XLOOKUP($E7,All_IDs!$B:$B,All_IDs!$A:$A),""))} -> item_scrap_metal | H7: {=IF($E7="","",IFERROR(XLOOKUP($E7,All_IDs!$B:$B,All_IDs!$D:$D),""))} -> Junk | I7: 18 | J7: 1 | K7: 1
A8: =IF($B8="","",N(A7)+1) -> 7 | B8: 하람의 파수꾼 | C8: {=IF($B8="","",IFERROR(XLOOKUP($B8,Monster!$B:$B,Monster!$C:$C),""))} -> Warden of Haram | D8: {=IF($B8="","",IFERROR(XLOOKUP($B8,Monster!$B:$B,Monster!$A:$A),""))} -> monster_haram_warden | E8: 원두 한 줌 | F8: {=IF($E8="","",IFERROR(XLOOKUP($E8,All_IDs!$B:$B,All_IDs!$C:$C),""))} -> Handful of Coffee Beans | G8: {=IF($E8="","",IFERROR(XLOOKUP($E8,All_IDs!$B:$B,All_IDs!$A:$A),""))} -> item_food_coffee | H8: {=IF($E8="","",IFERROR(XLOOKUP($E8,All_IDs!$B:$B,All_IDs!$D:$D),""))} -> Food | I8: 30 | J8: 1 | K8: 1
A9: =IF($B9="","",N(A8)+1) -> 8 | B9: 하람의 파수꾼 | C9: {=IF($B9="","",IFERROR(XLOOKUP($B9,Monster!$B:$B,Monster!$C:$C),""))} -> Warden of Haram | D9: {=IF($B9="","",IFERROR(XLOOKUP($B9,Monster!$B:$B,Monster!$A:$A),""))} -> monster_haram_warden | E9: 전자 부품 | F9: {=IF($E9="","",IFERROR(XLOOKUP($E9,All_IDs!$B:$B,All_IDs!$C:$C),""))} -> Electronic Parts | G9: {=IF($E9="","",IFERROR(XLOOKUP($E9,All_IDs!$B:$B,All_IDs!$A:$A),""))} -> item_electronic_parts | H9: {=IF($E9="","",IFERROR(XLOOKUP($E9,All_IDs!$B:$B,All_IDs!$D:$D),""))} -> Junk | I9: 25 | J9: 1 | K9: 1
A10: =IF($B10="","",N(A9)+1) -> 9 | B10: 하람의 파수꾼 | C10: {=IF($B10="","",IFERROR(XLOOKUP($B10,Monster!$B:$B,Monster!$C:$C),""))} -> Warden of Haram | D10: {=IF($B10="","",IFERROR(XLOOKUP($B10,Monster!$B:$B,Monster!$A:$A),""))} -> monster_haram_warden | E10: 고철 | F10: {=IF($E10="","",IFERROR(XLOOKUP($E10,All_IDs!$B:$B,All_IDs!$C:$C),""))} -> Scrap Metal | G10: {=IF($E10="","",IFERROR(XLOOKUP($E10,All_IDs!$B:$B,All_IDs!$A:$A),""))} -> item_scrap_metal | H10: {=IF($E10="","",IFERROR(XLOOKUP($E10,All_IDs!$B:$B,All_IDs!$D:$D),""))} -> Junk | I10: 15 | J10: 1 | K10: 1
A11: =IF($B11="","",N(A10)+1) -> 10 | B11: 골목길 불량배 | C11: {=IF($B11="","",IFERROR(XLOOKUP($B11,Monster!$B:$B,Monster!$C:$C),""))} -> Alley Thug | D11: {=IF($B11="","",IFERROR(XLOOKUP($B11,Monster!$B:$B,Monster!$A:$A),""))} -> monster_rogue_alley | E11: 목검 | F11: {=IF($E11="","",IFERROR(XLOOKUP($E11,All_IDs!$B:$B,All_IDs!$C:$C),""))} -> Wooden Sword | G11: {=IF($E11="","",IFERROR(XLOOKUP($E11,All_IDs!$B:$B,All_IDs!$A:$A),""))} -> weapon_wooden_sword | H11: {=IF($E11="","",IFERROR(XLOOKUP($E11,All_IDs!$B:$B,All_IDs!$D:$D),""))} -> Weapon | I11: 30 | J11: 1 | K11: 1
A12: =IF($B12="","",N(A11)+1) -> 11 | B12: 골목길 불량배 | C12: {=IF($B12="","",IFERROR(XLOOKUP($B12,Monster!$B:$B,Monster!$C:$C),""))} -> Alley Thug | D12: {=IF($B12="","",IFERROR(XLOOKUP($B12,Monster!$B:$B,Monster!$A:$A),""))} -> monster_rogue_alley | E12: 붕대 | F12: {=IF($E12="","",IFERROR(XLOOKUP($E12,All_IDs!$B:$B,All_IDs!$C:$C),""))} -> Bandage | G12: {=IF($E12="","",IFERROR(XLOOKUP($E12,All_IDs!$B:$B,All_IDs!$A:$A),""))} -> item_med_bandage | H12: {=IF($E12="","",IFERROR(XLOOKUP($E12,All_IDs!$B:$B,All_IDs!$D:$D),""))} -> Medicine | I12: 40 | J12: 1 | K12: 1
A13: =IF($B13="","",N(A12)+1) -> 12 | B13: 골목길 불량배 | C13: {=IF($B13="","",IFERROR(XLOOKUP($B13,Monster!$B:$B,Monster!$C:$C),""))} -> Alley Thug | D13: {=IF($B13="","",IFERROR(XLOOKUP($B13,Monster!$B:$B,Monster!$A:$A),""))} -> monster_rogue_alley | E13: 전자 부품 | F13: {=IF($E13="","",IFERROR(XLOOKUP($E13,All_IDs!$B:$B,All_IDs!$C:$C),""))} -> Electronic Parts | H13: {=IF($E13="","",IFERROR(XLOOKUP($E13,All_IDs!$B:$B,All_IDs!$D:$D),""))} -> Junk | I13: 20 | J13: 1 | K13: 1
A14: =IF($B14="","",N(A13)+1) | C14: {=IF($B14="","",IFERROR(XLOOKUP($B14,Monster!$B:$B,Monster!$C:$C),""))} | D14: {=IF($B14="","",IFERROR(XLOOKUP($B14,Monster!$B:$B,Monster!$A:$A),""))} | F14: {=IF($E14="","",IFERROR(XLOOKUP($E14,All_IDs!$B:$B,All_IDs!$C:$C),""))} | G14: {=IF($E14="","",IFERROR(XLOOKUP($E14,All_IDs!$B:$B,All_IDs!$A:$A),""))} | H14: {=IF($E14="","",IFERROR(XLOOKUP($E14,All_IDs!$B:$B,All_IDs!$D:$D),""))}
A15: =IF($B15="","",N(A14)+1) | C15: {=IF($B15="","",IFERROR(XLOOKUP($B15,Monster!$B:$B,Monster!$C:$C),""))} | D15: {=IF($B15="","",IFERROR(XLOOKUP($B15,Monster!$B:$B,Monster!$A:$A),""))} | F15: {=IF($E15="","",IFERROR(XLOOKUP($E15,All_IDs!$B:$B,All_IDs!$C:$C),""))} | G15: {=IF($E15="","",IFERROR(XLOOKUP($E15,All_IDs!$B:$B,All_IDs!$A:$A),""))} | H15: {=IF($E15="","",IFERROR(XLOOKUP($E15,All_IDs!$B:$B,All_IDs!$D:$D),""))}
A16: =IF($B16="","",N(A15)+1) | C16: {=IF($B16="","",IFERROR(XLOOKUP($B16,Monster!$B:$B,Monster!$C:$C),""))} | D16: {=IF($B16="","",IFERROR(XLOOKUP($B16,Monster!$B:$B,Monster!$A:$A),""))} | F16: {=IF($E16="","",IFERROR(XLOOKUP($E16,All_IDs!$B:$B,All_IDs!$C:$C),""))} | G16: {=IF($E16="","",IFERROR(XLOOKUP($E16,All_IDs!$B:$B,All_IDs!$A:$A),""))} | H16: {=IF($E16="","",IFERROR(XLOOKUP($E16,All_IDs!$B:$B,All_IDs!$D:$D),""))}
A17: =IF($B17="","",N(A16)+1) | C17: {=IF($B17="","",IFERROR(XLOOKUP($B17,Monster!$B:$B,Monster!$C:$C),""))} | D17: {=IF($B17="","",IFERROR(XLOOKUP($B17,Monster!$B:$B,Monster!$A:$A),""))} | F17: {=IF($E17="","",IFERROR(XLOOKUP($E17,All_IDs!$B:$B,All_IDs!$C:$C),""))} | G17: {=IF($E17="","",IFERROR(XLOOKUP($E17,All_IDs!$B:$B,All_IDs!$A:$A),""))} | H17: {=IF($E17="","",IFERROR(XLOOKUP($E17,All_IDs!$B:$B,All_IDs!$D:$D),""))}
A18: =IF($B18="","",N(A17)+1) | C18: {=IF($B18="","",IFERROR(XLOOKUP($B18,Monster!$B:$B,Monster!$C:$C),""))} | D18: {=IF($B18="","",IFERROR(XLOOKUP($B18,Monster!$B:$B,Monster!$A:$A),""))} | F18: {=IF($E18="","",IFERROR(XLOOKUP($E18,All_IDs!$B:$B,All_IDs!$C:$C),""))} | G18: {=IF($E18="","",IFERROR(XLOOKUP($E18,All_IDs!$B:$B,All_IDs!$A:$A),""))} | H18: {=IF($E18="","",IFERROR(XLOOKUP($E18,All_IDs!$B:$B,All_IDs!$D:$D),""))}
A19: =IF($B19="","",N(A18)+1) | C19: {=IF($B19="","",IFERROR(XLOOKUP($B19,Monster!$B:$B,Monster!$C:$C),""))} | D19: {=IF($B19="","",IFERROR(XLOOKUP($B19,Monster!$B:$B,Monster!$A:$A),""))} | F19: {=IF($E19="","",IFERROR(XLOOKUP($E19,All_IDs!$B:$B,All_IDs!$C:$C),""))} | G19: {=IF($E19="","",IFERROR(XLOOKUP($E19,All_IDs!$B:$B,All_IDs!$A:$A),""))} | H19: {=IF($E19="","",IFERROR(XLOOKUP($E19,All_IDs!$B:$B,All_IDs!$D:$D),""))}
A20: =IF($B20="","",N(A19)+1) | C20: {=IF($B20="","",IFERROR(XLOOKUP($B20,Monster!$B:$B,Monster!$C:$C),""))} | D20: {=IF($B20="","",IFERROR(XLOOKUP($B20,Monster!$B:$B,Monster!$A:$A),""))} | F20: {=IF($E20="","",IFERROR(XLOOKUP($E20,All_IDs!$B:$B,All_IDs!$C:$C),""))} | G20: {=IF($E20="","",IFERROR(XLOOKUP($E20,All_IDs!$B:$B,All_IDs!$A:$A),""))} | H20: {=IF($E20="","",IFERROR(XLOOKUP($E20,All_IDs!$B:$B,All_IDs!$D:$D),""))}
A21: =IF($B21="","",N(A20)+1) | C21: {=IF($B21="","",IFERROR(XLOOKUP($B21,Monster!$B:$B,Monster!$C:$C),""))} | D21: {=IF($B21="","",IFERROR(XLOOKUP($B21,Monster!$B:$B,Monster!$A:$A),""))} | F21: {=IF($E21="","",IFERROR(XLOOKUP($E21,All_IDs!$B:$B,All_IDs!$C:$C),""))} | G21: {=IF($E21="","",IFERROR(XLOOKUP($E21,All_IDs!$B:$B,All_IDs!$A:$A),""))} | H21: {=IF($E21="","",IFERROR(XLOOKUP($E21,All_IDs!$B:$B,All_IDs!$D:$D),""))}
A22: =IF($B22="","",N(A21)+1) | C22: {=IF($B22="","",IFERROR(XLOOKUP($B22,Monster!$B:$B,Monster!$C:$C),""))} | D22: {=IF($B22="","",IFERROR(XLOOKUP($B22,Monster!$B:$B,Monster!$A:$A),""))} | F22: {=IF($E22="","",IFERROR(XLOOKUP($E22,All_IDs!$B:$B,All_IDs!$C:$C),""))} | G22: {=IF($E22="","",IFERROR(XLOOKUP($E22,All_IDs!$B:$B,All_IDs!$A:$A),""))} | H22: {=IF($E22="","",IFERROR(XLOOKUP($E22,All_IDs!$B:$B,All_IDs!$D:$D),""))}
A23: =IF($B23="","",N(A22)+1) | C23: {=IF($B23="","",IFERROR(XLOOKUP($B23,Monster!$B:$B,Monster!$C:$C),""))} | D23: {=IF($B23="","",IFERROR(XLOOKUP($B23,Monster!$B:$B,Monster!$A:$A),""))} | F23: {=IF($E23="","",IFERROR(XLOOKUP($E23,All_IDs!$B:$B,All_IDs!$C:$C),""))} | G23: {=IF($E23="","",IFERROR(XLOOKUP($E23,All_IDs!$B:$B,All_IDs!$A:$A),""))} | H23: {=IF($E23="","",IFERROR(XLOOKUP($E23,All_IDs!$B:$B,All_IDs!$D:$D),""))}
A24: =IF($B24="","",N(A23)+1) | C24: {=IF($B24="","",IFERROR(XLOOKUP($B24,Monster!$B:$B,Monster!$C:$C),""))} | D24: {=IF($B24="","",IFERROR(XLOOKUP($B24,Monster!$B:$B,Monster!$A:$A),""))} | F24: {=IF($E24="","",IFERROR(XLOOKUP($E24,All_IDs!$B:$B,All_IDs!$C:$C),""))} | G24: {=IF($E24="","",IFERROR(XLOOKUP($E24,All_IDs!$B:$B,All_IDs!$A:$A),""))} | H24: {=IF($E24="","",IFERROR(XLOOKUP($E24,All_IDs!$B:$B,All_IDs!$D:$D),""))}
A25: =IF($B25="","",N(A24)+1) | C25: {=IF($B25="","",IFERROR(XLOOKUP($B25,Monster!$B:$B,Monster!$C:$C),""))} | D25: {=IF($B25="","",IFERROR(XLOOKUP($B25,Monster!$B:$B,Monster!$A:$A),""))} | F25: {=IF($E25="","",IFERROR(XLOOKUP($E25,All_IDs!$B:$B,All_IDs!$C:$C),""))} | G25: {=IF($E25="","",IFERROR(XLOOKUP($E25,All_IDs!$B:$B,All_IDs!$A:$A),""))} | H25: {=IF($E25="","",IFERROR(XLOOKUP($E25,All_IDs!$B:$B,All_IDs!$D:$D),""))}
